<?xml version="1.0" ?>
<!-- =================================================================================== -->
<!-- |    This document was autogenerated by xacro from /home/lex/catkin_ws/src/superchicko/superchick/novalis.xacro | -->
<!-- |    EDITING THIS FILE BY HAND IS NOT RECOMMENDED                                 | -->
<!-- =================================================================================== -->
<robot name="novalis" xmlns:xacro="http://www.ros.org/wiki/xacro">
  <!-- Part of the Model for the Novalis TX Spec
      Author: Olalekan Ogunmolu, August 2016
  -->
  <!-- Derived Variables -->
  <material name="novalis_color">
    <color rgba="0.662745 0.662745 0.662745 1"/>
  </material>
  <material name="blue">
    <color rgba="0 0 .8 1"/>
  </material>
  <material name="black">
    <color rgba="0 0 0 1"/>
  </material>
  <material name="white">
    <color rgba="1 1 1 1"/>
  </material>
  <!-- this is the 6-DOF bed -->
  <link name="base_link">
    <visual>
      <origin rpy="0 0 0" xyz="0 0 0"/>
      <geometry>
        <box size="2.584 1.65 0.32"/>
      </geometry>
      <material name="novalis_color"/>
      <origin rpy="0 0 0" xyz="0 0 0"/>
    </visual>
    <collision>
      <geometry>
        <box size="2.584 1.65 0.32"/>
      </geometry>
    </collision>
  </link>
  <!-- cushion link 1 -->
  <link name="cush_link1">
    <visual>
      <origin rpy="0 0 0" xyz="0 0 0.1"/>
      <geometry>
        <box size="2.084 1.33 0.028"/>
      </geometry>
      <material name="novalis_color"/>
      <origin rpy="0 0 0" xyz="0 0 0.1"/>
    </visual>
    <collision>
      <geometry>
        <box size="2.084 1.33 0.028"/>
      </geometry>
      <origin rpy="0 0 0" xyz="0 0 0.1"/>
    </collision>
  </link>
  <joint name="base_link_to_cush_link1" type="continuous">
    <parent link="base_link"/>
    <child link="cush_link1"/>
    <origin xyz="0 0 0"/>
  </joint>
  <!--cushion  link 2 -->
  <link name="cush_link2">
    <visual>
      <origin rpy="0 0 0" xyz="0 0 0.2"/>
      <geometry>
        <box size="2.084 1.33 0.028"/>
      </geometry>
      <material name="novalis_color"/>
      <origin rpy="0 0 0" xyz="0 0 0.2"/>
    </visual>
    <collision>
      <geometry>
        <box size="2.084 1.33 0.028"/>
      </geometry>
      <origin rpy="0 0 0" xyz="0 0 0.2"/>
    </collision>
  </link>
  <joint name="cush_link1_to_cush_link2" type="continuous">
    <parent link="cush_link1"/>
    <child link="cush_link2"/>
    <origin xyz="0 0 0"/>
  </joint>
  <!-- cushion link 3 -->
  <link name="cush_link3">
    <visual>
      <origin rpy="0 0 0" xyz="0 0 0.3"/>
      <geometry>
        <box size="2.084 1.33 0.028"/>
      </geometry>
      <material name="novalis_color"/>
      <origin rpy="0 0 0" xyz="0 0 0.3"/>
    </visual>
    <collision>
      <geometry>
        <box size="2.084 1.33 0.028"/>
      </geometry>
      <origin rpy="0 0 0" xyz="0 0 0.3"/>
    </collision>
  </link>
  <joint name="cush_link2_to_cush_link3" type="continuous">
    <parent link="cush_link2"/>
    <child link="cush_link3"/>
    <origin xyz="0 0 0"/>
  </joint>
  <!--cushion  link 4 -->
  <link name="cush_link4">
    <visual>
      <origin rpy="0 0 0" xyz="0 0 0.4"/>
      <geometry>
        <box size="2.084 1.33 0.028"/>
      </geometry>
      <material name="novalis_color"/>
      <origin rpy="0 0 0" xyz="0 0 0.4"/>
    </visual>
    <collision>
      <geometry>
        <box size="2.084 1.33 0.028"/>
      </geometry>
      <origin rpy="0 0 0" xyz="0 0 0.4"/>
    </collision>
  </link>
  <joint name="cush_link3_to_cush_link4" type="continuous">
    <parent link="cush_link3"/>
    <child link="cush_link4"/>
    <origin xyz="0 0 0"/>
  </joint>
  <!--cushion  link 5 -->
  <link name="cush_link5">
    <visual>
      <origin rpy="0 0 0" xyz="0 0 0.5"/>
      <geometry>
        <box size="2.084 1.33 0.028"/>
      </geometry>
      <material name="novalis_color"/>
      <origin rpy="0 0 0" xyz="0 0 0.5"/>
    </visual>
    <collision>
      <geometry>
        <box size="2.084 1.33 0.028"/>
      </geometry>
      <origin rpy="0 0 0" xyz="0 0 0.5"/>
    </collision>
  </link>
  <joint name="cush_link4_to_cush_link5" type="continuous">
    <parent link="cush_link4"/>
    <child link="cush_link5"/>
    <origin xyz="0 0 0"/>
  </joint>
  <!--cushion  link 6 -->
  <link name="cush_link6">
    <visual>
      <origin rpy="0 0 0" xyz="0 0 0.6"/>
      <geometry>
        <box size="2.084 1.33 0.028"/>
      </geometry>
      <material name="novalis_color"/>
      <origin rpy="0 0 0" xyz="0 0 0.6"/>
    </visual>
    <collision>
      <geometry>
        <box size="2.084 1.33 0.028"/>
      </geometry>
      <origin rpy="0 0 0" xyz="0 0 0.6"/>
    </collision>
  </link>
  <joint name="cush_link5_to_cush_link6" type="continuous">
    <parent link="cush_link5"/>
    <child link="cush_link6"/>
    <origin xyz="0 0 0"/>
  </joint>
  <!--cushion  link7 -->
  <link name="cush_link7">
    <visual>
      <origin rpy="0 0 0" xyz="0 0 0.7"/>
      <geometry>
        <box size="2.084 1.33 0.028"/>
      </geometry>
      <material name="novalis_color"/>
      <origin rpy="0 0 0" xyz="0 0 0.7"/>
    </visual>
    <collision>
      <geometry>
        <box size="2.084 1.33 0.028"/>
      </geometry>
      <origin rpy="0 0 0" xyz="0 0 0.7"/>
    </collision>
  </link>
  <joint name="cush_link6_to_cush_link7" type="continuous">
    <parent link="cush_link6"/>
    <child link="cush_link7"/>
    <origin xyz="0 0 0"/>
  </joint>
  <!--cushion  link8 -->
  <link name="cush_link8">
    <visual>
      <origin rpy="0 0 0" xyz="0 0 0.8"/>
      <geometry>
        <box size="2.084 1.33 0.028"/>
      </geometry>
      <material name="novalis_color"/>
      <origin rpy="0 0 0" xyz="0 0 0.8"/>
    </visual>
    <collision>
      <geometry>
        <box size="2.084 1.33 0.028"/>
      </geometry>
      <origin rpy="0 0 0" xyz="0 0 0.8"/>
    </collision>
  </link>
  <joint name="cush_link7_to_cush_link8" type="continuous">
    <parent link="cush_link7"/>
    <child link="cush_link8"/>
    <origin xyz="0 0 0"/>
  </joint>
  <!--cushion link9 -->
  <link name="cush_link9">
    <visual>
      <origin rpy="0 0 0" xyz="0 0 0.9"/>
      <geometry>
        <box size="2.084 1.33 0.028"/>
      </geometry>
      <material name="novalis_color"/>
      <origin rpy="0 0 0" xyz="0 0 0.9"/>
    </visual>
    <collision>
      <geometry>
        <box size="2.084 1.33 0.028"/>
      </geometry>
      <origin rpy="0 0 0" xyz="0 0 0.9"/>
    </collision>
  </link>
  <joint name="cush_link8_to_cush_link9" type="continuous">
    <parent link="cush_link8"/>
    <child link="cush_link9"/>
    <origin xyz="0 0 0"/>
  </joint>
  <!--cushion link10 -->
  <link name="cush_link10">
    <visual>
      <origin rpy="0 0 0" xyz="0 0 1.0"/>
      <geometry>
        <box size="2.084 1.33 0.028"/>
      </geometry>
      <material name="novalis_color"/>
      <origin rpy="0 0 0" xyz="0 0 1.0"/>
    </visual>
    <collision>
      <geometry>
        <box size="2.084 1.33 0.028"/>
      </geometry>
      <origin rpy="0 0 0" xyz="0 0 1.0"/>
    </collision>
  </link>
  <joint name="cush_link9_to_cush_link10" type="continuous">
    <parent link="cush_link9"/>
    <child link="cush_link10"/>
    <origin xyz="0 0 0"/>
  </joint>
  <!--cushion link11 -->
  <link name="cush_link11">
    <visual>
      &quot;
      
      <origin rpy="0 0 0" xyz="0 0 1.1"/>
      <geometry>
        <box size="2.084 1.33 0.028"/>
      </geometry>
      <material name="novalis_color"/>
      <origin rpy="0 0 0" xyz="0 0 1.1"/>
    </visual>
    <collision>
      <geometry>
        <box size="2.084 1.33 0.028"/>
      </geometry>
      <origin rpy="0 0 0" xyz="0 0 1.1"/>
    </collision>
  </link>
  <joint name="cush_link10_to_cush_link11" type="continuous">
    <parent link="cush_link10"/>
    <child link="cush_link11"/>
    <origin xyz="0 0 0"/>
  </joint>
  <!--cushion link12-->
  <link name="cush_link12">
    <visual>
      <origin rpy="0 0 0" xyz="0 0 1.2"/>
      <geometry>
        <box size="2.084 1.33 0.028"/>
      </geometry>
      <material name="novalis_color"/>
      <origin rpy="0 0 0" xyz="0 0 1.2"/>
    </visual>
    <collision>
      <geometry>
        <box size="2.084 1.33 0.028"/>
      </geometry>
      <origin rpy="0 0 0" xyz="0 0 1.2"/>
    </collision>
  </link>
  <joint name="cush_link11_to_cush_link12" type="continuous">
    <parent link="cush_link11"/>
    <child link="cush_link12"/>
    <origin xyz="0 0 0"/>
  </joint>
  <!--cushion link13-->
  <link name="cush_link13">
    <visual>
      <origin rpy="0 0 0" xyz="0 0 1.3"/>
      <geometry>
        <box size="2.084 1.33 0.028"/>
      </geometry>
      <material name="novalis_color"/>
      <origin rpy="0 0 0" xyz="0 0 1.3"/>
    </visual>
    <collision>
      <geometry>
        <box size="2.084 1.33 0.028"/>
      </geometry>
      <origin rpy="0 0 0" xyz="0 0 1.3"/>
    </collision>
  </link>
  <joint name="cush_link12_to_cush_link13" type="continuous">
    <parent link="cush_link12"/>
    <child link="cush_link13"/>
    <origin xyz="0 0 0"/>
    x
  
  </joint>
  <link name="bed_base">
    <visual>
      <origin rpy=" 0 0 0" xyz="0 0 1.4"/>
      <geometry>
        <box size="2.554 1.55 0.42"/>
      </geometry>
      <material name="blue"/>
      <origin rpy=" 0 0 0" xyz="0 0 1.4"/>
    </visual>
    <collision>
      <geometry>
        <box size="2.554 1.55 0.42"/>
      </geometry>
    </collision>
  </link>
  <joint name="bed_base_to_cush_link13" type="fixed">
    <parent link="cush_link13"/>
    <child link="bed_base"/>
    <origin xyz="0 0 1.35"/>
  </joint>
</robot>
