<?xml version="1.0" ?>
<!-- =================================================================================== -->
<!-- |    This document was autogenerated by xacro from superchick.xacro               | -->
<!-- |    EDITING THIS FILE BY HAND IS NOT RECOMMENDED                                 | -->
<!-- =================================================================================== -->
<robot name="superchick" xmlns:xacro="http://www.ros.org/wiki/xacro">
  <!-- <xacro:include filename="$(find superchick)/superchick.gazebo" /> -->
  <!-- General Properties -->
  <!-- This file contains the table and bladder descriptions -->
  <!-- Matrial Girl 
    Lekan Ogunmolu-->
  <material name="table_color">
    <color rgba="0.8 0.8 0.8 1"/>
  </material>
  <material name="blue">
    <color rgba="0 0 .8 1"/>
  </material>
  <material name="table_cover_color">
    <color rgba="0 0.101960784314 0.2 1"/>
  </material>
  <material name="dark_gray">
    <color rgba="0.156863 0.156863 0.156863 1"/>
  </material>
  <material name="vicon_red">
    <color rgba="1 0 0 1"/>
  </material>
  <material name="white">
    <color rgba="1 1 1 1"/>
  </material>
  <material name="base_color">
    <color rgba="0 0 0 0"/>
  </material>
  <material name="brown">
    <color rgba="0.647059 0.164706 0.164706 1"/>
  </material>
  <material name="bladder_color">
    <color rgba="1.0 1.0 0 1.0"/>
  </material>
  <material name="panel_color">
    <color rgba="0.133 0.55 0.13 1"/>
  </material>
  <!-- Model for the Superchick Table Spec
      Author: Olalekan Ogunmolu, August 2016

        Generate urdf with 
        rosrun xacro xacro src/superchick/table.xacro > table.urdf
        Then run with 

        roslaunch superchick display.launch model:=table.urdf 
  -->
  <!-- table top properties -->
  <!-- table leg properties -->
  <!-- table leg base properties -->
  <!-- @TODO: not to scale distance between two legs -->
  <!-- table cover properties -->
  <!-- table legs artificial base link -->
  <link name="world">
    <visual>
      <origin rpy="0 0 0" xyz="0 0 0"/>
      <geometry>
        <box size="1.524 0.6198 0.0381"/>
      </geometry>
      <material name="base_color"/>
      <origin rpy="0 0 0" xyz="0 0 0"/>
    </visual>
    <collision>
      <geometry>
        <box size="1.524 0.6198 0.0381"/>
      </geometry>
    </collision>
    <!-- KDL does not support root link inertia mass -->
  </link>
  <!-- right leg -->
  <link name="right_leg">
    <visual>
      <geometry>
        <box size="0.635 0.1778 0.0254"/>
      </geometry>
      <origin rpy="0 1.57075 0" xyz="0 0 0"/>
      <material name="dark_gray"/>
    </visual>
    <collision>
      <geometry>
        <box size="0.635 0.1778 0.0254"/>
      </geometry>
      <origin rpy="0 1.57075 0" xyz="0 0 0"/>
    </collision>
    <inertial>
      <mass value="0.01"/>
      <inertia ixx="0.000833333333333" ixy="0.0" ixz="0.0" iyy="0.000833333333333" iyz="0.0000" izz="0.000833333333333"/>
    </inertial>
  </link>
  <!-- join right leg to base -->
  <joint name="base_to_right_leg" type="fixed">
    <parent link="world"/>
    <child link="right_leg"/>
    <origin xyz="0.6858 0 0.3"/>
  </joint>
  <!-- draw left leg -->
  <link name="left_leg">
    <visual>
      <geometry>
        <box size="0.635 0.1778 0.0254"/>
      </geometry>
      <origin rpy="0 1.57075 0" xyz="0 0 0"/>
      <material name="dark_gray"/>
    </visual>
    <collision>
      <geometry>
        <box size="0.635 0.1778 0.0254"/>
      </geometry>
      <origin rpy="0 1.57075 0" xyz="0 0 0"/>
    </collision>
    <inertial>
      <mass value="0.01"/>
      <inertia ixx="0.000833333333333" ixy="0.0" ixz="0.0" iyy="0.000833333333333" iyz="0.0000" izz="0.000833333333333"/>
    </inertial>
  </link>
  <!-- join left leg to base -->
  <joint name="base_to_left_leg" type="fixed">
    <parent link="world"/>
    <child link="left_leg"/>
    <origin xyz="-0.6858 0 0.3"/>
  </joint>
  <!-- Overlay table top -->
  <link name="table_top">
    <visual>
      <origin rpy="0 0 0" xyz="0 0 -0.015"/>
      <geometry>
        <box size="1.524 0.6198 0.0381"/>
      </geometry>
      <material name="table_color"/>
      <origin rpy="0 0 0" xyz="0 0 -0.015"/>
    </visual>
    <collision>
      <geometry>
        <box size="1.524 0.6198 0.0381"/>
      </geometry>
    </collision>
    <inertial>
      <mass value="0.01"/>
      <inertia ixx="0.000833333333333" ixy="0.0" ixz="0.0" iyy="0.000833333333333" iyz="0.0000" izz="0.000833333333333"/>
    </inertial>
  </link>
  <joint name="rightleg_to_tabletop" type="fixed">
    <parent link="right_leg"/>
    <child link="table_top"/>
    <origin xyz="-0.6858 0 0.35 "/>
  </joint>
  <joint name="leftleg_to_tabletop" type="fixed">
    <parent link="left_leg"/>
    <child link="table_top"/>
    <origin xyz="-0.6858 0 0.35 "/>
  </joint>
  <link name="table_cover">
    <visual>
      <origin rpy="0 0 0" xyz="0 0 -0.0381"/>
      <geometry>
        <box size="1.524 0.2794 0.227"/>
      </geometry>
      <material name="table_cover_color"/>
      <origin rpy="0 0 0" xyz="0 0 -0.0381"/>
    </visual>
    <collision>
      <geometry>
        <box size="1.524 0.2794 0.227"/>
      </geometry>
    </collision>
    <inertial>
      <mass value="0.01"/>
      <inertia ixx="0.000833333333333" ixy="0.0" ixz="0.0" iyy="0.000833333333333" iyz="0.0000" izz="0.000833333333333"/>
    </inertial>
  </link>
  <joint name="tablecover_to_tabletop" type="fixed">
    <parent link="table_top"/>
    <child link="table_cover"/>
    <origin rpy="-1.570795 0 0 " xyz="0 0.2299 -0.18"/>
  </joint>
  <!-- General Properties -->
  <!-- Lekan Ogunmolu | November 2016 -->
  <link name="right_bladder">
    <visual>
      <origin rpy="0 0 0" xyz="0 0 0"/>
      <geometry>
        <box size="0.15748 0.15748 0.0508"/>
      </geometry>
      <material name="bladder_color"/>
      <origin rpy="0 0 0" xyz="0 0 0"/>
    </visual>
    <collision>
      <geometry>
        <box size="0.15748 0.15748 0.0508"/>
      </geometry>
      <origin rpy="0 0 0" xyz="0 0 0"/>
    </collision>
    <inertial>
      <mass value="0.01"/>
      <inertia ixx="0.000833333333333" ixy="0.0" ixz="0.0" iyy="0.000833333333333" iyz="0.0000" izz="0.000833333333333"/>
    </inertial>
  </link>
  <link name="left_bladder">
    <visual>
      <origin rpy="0 0 0" xyz="0 0.05 0"/>
      <geometry>
        <box size="0.15748 0.15748 0.0508"/>
      </geometry>
      <material name="bladder_color"/>
      <origin rpy="0 0 0" xyz="0 0.05 0"/>
    </visual>
    <collision>
      <geometry>
        <box size="0.15748 0.15748 0.0508"/>
      </geometry>
      <origin rpy="0 0 0" xyz="0 0.05 0"/>
    </collision>
    <inertial>
      <mass value="0.01"/>
      <inertia ixx="0.000833333333333" ixy="0.0" ixz="0.0" iyy="0.000833333333333" iyz="0.0000" izz="0.000833333333333"/>
    </inertial>
  </link>
  <link name="big_bladder_link">
    <visual>
      <origin rpy="0 0 0" xyz="0 0 0"/>
      <geometry>
        <box size="0.31496 0.31496 0.0508"/>
      </geometry>
      <material name="bladder_color"/>
      <origin rpy="0 0 0" xyz="0 0 0"/>
    </visual>
    <collision>
      <geometry>
        <box size="0.31496 0.31496 0.1016"/>
      </geometry>
      <origin rpy="0 0 0" xyz="0 0 0"/>
    </collision>
    <inertial>
      <mass value="0.01"/>
      <inertia ixx="0.000833333333333" ixy="0.0" ixz="0.0" iyy="0.000833333333333" iyz="0.0000" izz="0.000833333333333"/>
    </inertial>
  </link>
  <!-- General Properties -->
  <!-- inflatable air bladder -->
  <link name="headnball_link">
    <visual>
      <origin rpy="1.570795 0 -3.14159" xyz="0.0 -0.15 0.0366666666667"/>
      <geometry>
        <mesh filename="package://superchick/meshes/headnball.stl" scale=".001 .001 .001"/>
      </geometry>
      <material name="brown"/>
      <origin rpy="1.570795 0 -3.14159" xyz="0.0 -0.15 0.0366666666667"/>
    </visual>
    <collision>
      <geometry>
        <mesh filename="package://superchick/meshes/headnball.stl" scale=".001 .001 .001"/>
      </geometry>
      <origin rpy="1.570795 0 -3.14159" xyz="0.0 -0.15 0.0366666666667"/>
    </collision>
    <inertial>
      <mass value="0.01"/>
      <inertia ixx="0.000833333333333" ixy="0.0" ixz="0.0" iyy="0.000833333333333" iyz="0.0000" izz="0.000833333333333"/>
    </inertial>
    <!--      <inertial>
       <mass value="1e-1"/>
       <inertia ixx="0.925288" ixy="0.379102" ixz="0.011081" 
                iyy="0.919140" iyz="0.111180" izz="0.993738"/>
     </inertial> -->
  </link>
  <!-- Description: Head Cage

	 Author: Alex Tomkovich, September 27, 2016
	 Modified: Lekan Ogunmolu Nov. 18, 2016
 	-->
  <!-- Panel Properties -->
  <link name="base_panel">
    <visual>
      <geometry>
        <box size="0.5842 0.2794 0.0047625"/>
      </geometry>
      <origin rpy="0 0 0" xyz="0 0 0"/>
      <material name="panel_color"/>
    </visual>
    <collision>
      <geometry>
        <box size="0.5842 0.2794 0.0047625"/>
      </geometry>
      <origin rpy="0 0 0" xyz="0 0 0"/>
    </collision>
    <inertial>
      <mass value="0.01"/>
      <inertia ixx="0.000833333333333" ixy="0.0" ixz="0.0" iyy="0.000833333333333" iyz="0.0000" izz="0.000833333333333"/>
    </inertial>
  </link>
  <!-- 12:00 panel -->
  <link name="panel_12_oc">
    <visual>
      <geometry>
        <box size="0.47 0.200025 0.0047625"/>
      </geometry>
      <material name="panel_color"/>
      <origin rpy="1.570795 0 0" xyz="0 0 0"/>
    </visual>
    <collision>
      <geometry>
        <box size="0.47 0.200025 0.0047625"/>
      </geometry>
      <origin rpy="1.570795 0 0" xyz="0 0 0"/>
    </collision>
    <inertial>
      <mass value="0.01"/>
      <inertia ixx="0.000833333333333" ixy="0.0" ixz="0.0" iyy="0.000833333333333" iyz="0.0000" izz="0.000833333333333"/>
    </inertial>
  </link>
  <!-- Join 12:00 Panel to base_panel -->
  <joint name="base_panel_to_12oc" type="fixed">
    <parent link="base_panel"/>
    <child link="panel_12_oc"/>
    <origin xyz="0 0.09398 0.10239375"/>
  </joint>
  <!-- 9:00 Panel -->
  <link name="panel_9_oc">
    <visual>
      <origin rpy="1.570795 0 1.570795" xyz="0 0 0"/>
      <geometry>
        <box size="0.231775 0.200025 0.0047625"/>
      </geometry>
      <material name="panel_color"/>
    </visual>
    <collision>
      <geometry>
        <box size="0.231775 0.200025 0.0047625"/>
      </geometry>
      <origin rpy="1.570795 0 1.570795" xyz="0 0 0"/>
    </collision>
    <inertial>
      <mass value="0.01"/>
      <inertia ixx="0.000833333333333" ixy="0.0" ixz="0.0" iyy="0.000833333333333" iyz="0.0000" izz="0.000833333333333"/>
    </inertial>
  </link>
  <!-- Join 9:00 Panel to 12:00 Panel -->
  <joint name="12oc_to_9oc" type="fixed">
    <parent link="panel_12_oc"/>
    <child link="panel_9_oc"/>
    <origin xyz="-0.23738125 -0.11350625 0"/>
  </joint>
  <!-- 3:00 Panel -->
  <link name="panel_3_oc">
    <visual>
      <origin rpy="1.570795 0 1.570795" xyz="0 0 0"/>
      <geometry>
        <box size="0.231775 0.200025 0.0047625"/>
      </geometry>
      <material name="panel_color"/>
    </visual>
    <collision>
      <geometry>
        <box size="0.231775 0.200025 0.0047625"/>
      </geometry>
      <origin rpy="1.570795 0 1.570795" xyz="0 0 0"/>
    </collision>
    <inertial>
      <mass value="0.01"/>
      <inertia ixx="0.000833333333333" ixy="0.0" ixz="0.0" iyy="0.000833333333333" iyz="0.0000" izz="0.000833333333333"/>
    </inertial>
  </link>
  <!-- Join 3:00 Panel to 12:00 Panel -->
  <joint name="12oc_to_3oc" type="fixed">
    <parent link="panel_12_oc"/>
    <child link="panel_3_oc"/>
    <origin xyz="0.23738125 -0.11350625 0"/>
  </joint>
  <!-- General Properties -->
  <!-- vicon Frame-->
  <link name="vicon_frame">
    <visual>
      <origin rpy="1.570795 0 1.570795" xyz="0 0 0"/>
      <geometry>
        <mesh filename="package://superchick/meshes/vicon2.dae" scale=".001 .001 .001"/>
      </geometry>
      <material name="vicon_red"/>
    </visual>
    <collision>
      <origin rpy="1.570795 0 1.570795" xyz="0 0 0"/>
      <geometry>
        <mesh filename="package://superchick/meshes/vicon2.dae" scale=".001 .001 .001"/>
      </geometry>
      <material name="vicon_red"/>
    </collision>
    <inertial>
      <mass value="0.01"/>
      <inertia ixx="0.000833333333333" ixy="0.0" ixz="0.0" iyy="0.000833333333333" iyz="0.0000" izz="0.000833333333333"/>
    </inertial>
  </link>
  <!-- table link to bladders -->
  <joint name="table_to_big_bladder" type="fixed">
    <parent link="table_top"/>
    <child link="big_bladder_link"/>
    <limit effort="200.0" lower="0.1016" upper="0.1016" velocity="1.0"/>
    <safety_controller k_position="15" k_velocity="10" soft_lower_limit="-0.05" soft_upper_limit="0.05"/>
    <origin rpy="0.0 0 0.0" xyz="-0.532 0 0.0333333333333"/>
  </joint>
  <joint name="table_to_rightneckbladder" type="fixed">
    <parent link="table_top"/>
    <child link="right_bladder"/>
    <limit effort="200.0" lower="0.1016" upper="0.1016" velocity="1.0"/>
    <safety_controller k_position="15" k_velocity="10" soft_lower_limit="-0.05" soft_upper_limit="0.05"/>
    <origin rpy="0.0 0 0.0" xyz="-0.358 0.12 0.03125"/>
  </joint>
  <joint name="table_to_leftneckbladder" type="fixed">
    <parent link="table_top"/>
    <child link="left_bladder"/>
    <limit effort="200.0" lower="0.1016" upper="0.1016" velocity="1.0"/>
    <safety_controller k_position="15" k_velocity="10" soft_lower_limit="-0.05" soft_upper_limit="0.05"/>
    <origin rpy="0.0 0 0.0" xyz="-0.358 -0.12 0.03125"/>
  </joint>
  <!-- Actuator Links -->
  <joint name="bigbladder_to_head" type="continuous">
    <axis rpy="0 0 0" xyz="1 0 0"/>
    <parent link="big_bladder_link"/>
    <child link="headnball_link"/>
    <limit effort="200.0" lower="-0.1016" upper="0.1016" velocity="1.0"/>
    <safety_controller k_position="15" k_velocity="10" soft_lower_limit="-0.0" soft_upper_limit="0.3"/>
    <origin rpy="0 0 1.570795" xyz="0.15 0.1033 0"/>
  </joint>
  <joint name="rightbladder_to_neck" type="continuous">
    <axis rpy="0 0 0" xyz="1 -1 0"/>
    <parent link="right_bladder"/>
    <child link="headnball_link"/>
    <limit effort="200.0" lower="-0.1016" upper="0.1016" velocity="1.0"/>
    <dynamics damping="0.1" friction="0.2"/>
    <safety_controller k_position="15" k_velocity="10" soft_lower_limit="0.0" soft_upper_limit="0.3"/>
    <origin rpy="0 0 1.570795" xyz="0 0 0"/>
  </joint>
  <joint name="leftbladder_to_neck" type="continuous">
    <axis rpy="0 0 0" xyz="1 1 0"/>
    <parent link="left_bladder"/>
    <child link="headnball_link"/>
    <limit effort="200.0" lower="-0.1016" upper="0.1016" velocity="1.0"/>
    <dynamics damping="0.1" friction="0.2"/>
    <safety_controller k_position="15" k_velocity="10" soft_lower_limit="0.0" soft_upper_limit="0.3"/>
    <dynamics damping="0.1" friction="0.2"/>
    <origin rpy="0 0 1.570795" xyz="0 0.25 0"/>
  </joint>
  <joint name="tableTop_to_basePanel" type="fixed">
    <parent link="table_top"/>
    <child link="base_panel"/>
    <origin rpy="0.0 0 1.570795" xyz="-0.612 0 0.0125"/>
  </joint>
  <joint name="vicon_to_world" type="fixed">
    <parent link="world"/>
    <child link="vicon_frame"/>
    <origin rpy="0 0 0" xyz="-5 -4 2.00"/>
  </joint>
</robot>

