<mujoco model="superchick">
<asset>
	<material name="table_color" rgba="0.8 0.8 0.8 1" />
	<material name="blue" rgba="0 0 .8 1" />
	<material name="table_cover_color" rgba="0 0.101960784314 0.2 1" />
	<material name="dark_gray" rgba="0.156863 0.156863 0.156863 1" />
	<material name="vicon_red" rgba="1 0 0 1" />
	<material name="white" rgba="1 1 1 1" />
	<material name="base_color" rgba="0 0 0 0" />
	<material name="brown" rgba="0.647059 0.164706 0.164706 1" />
	<material name="bladder_color" rgba="1.0 1.0 0 1.0" />
	<material name="panel_color" rgba="0.133 0.55 0.13 1" />
	<mesh name="headnball_mesh" file="/home/lex/catkin_ws/src/superchicko/superchick/meshes/headnball.stl" scale=".001 .001 .001"/>
</asset>
<worldbody>
	<!-- World params?-->

	<body name="right_leg">
		<geom type="box" size="0.635 0.1778 0.0254" pos="0.6858 0 0.3" material="dark_gray" euler="0 90 0" />
		<inertial pos="0 0 0" mass=".01" diaginertia="166.667 166.667 166.667"/>
	</body>

	<body name="left_leg">
		<geom type="box" size="0.635 0.1778 0.0254" pos="-0.6858 0 0.3" material="dark_gray" euler="0 90 0" />
		<inertial pos="0 0 0" mass=".01" diaginertia="166.667 166.667 166.667"/>
	</body>

	<body name="table_top">
		<geom type="box" size="1.524 0.6198 0.0381" pos="0 0 .9731" material="table_color" euler="0 0 180" />
		<inertial pos="0 0 0" mass=".01" diaginertia="166.667 166.667 166.667"/>
	</body>

	<body name="table_cover">
		<geom type="box" size="1.524 0.2794 0.227" pos="0 0.3928 .656" material="table_cover_color" euler="-90 0 0" />
	</body>

	<body name="left_head_bladder">
		<geom type="ellipsoid" size="0.1 0.05 0.03" pos="0.532 0.07 1.062" material="bladder_color" euler="30 -20 0" />
		<joint name="left_head" type="hinge" pos="0.482 0.045 .885" axis="45 -20 0" limited="true" range="-15 30"/>
	</body>
	<body name="right_head_bladder">
		<geom type="ellipsoid" size="0.1 0.05 0.03" pos="0.532 -0.07 1.062" material="bladder_color" euler="-30 -20 0" />
		<joint name="right_head" type="hinge" pos="0.482 -0.045 .885" axis="-45 -20 0" limited="true" range="-15 30"/>
	</body>
	<body name="left_neck_bladder">
		<geom type="ellipsoid" size="0.1 0.05 0.03" pos="0.35 0.07 1.062" material="bladder_color" euler="30 20 0" />
	    <joint name="left_neck" type="hinge" pos="0.3 0.0675 .9" axis="45 20 0" stiffness=".1" limited="true" range="-15 30"/>
	</body>
	<body name="right_neck_bladder">
		<geom type="ellipsoid" size="0.1 0.05 0.03" pos="0.35 -0.07 1.062" material="bladder_color" euler="-30 20 0" />
	    <joint name="right_neck" type="hinge" pos="0.3 -0.0675 .9" axis="-45 20 0" limited="true" range="-15 30"/>
	</body>


	<body name="headnball">
		<geom type="mesh" mesh="headnball_mesh" euler="90 90 0" material="brown" pos="0.17 -0.08 1.1"/>
		<joint name="head_ball" type="ball" pos="0.17 -0.1 1.012" />
	</body>

	<body name="panel_12_oc">
		<geom type="box" size="0.231775 0.200025 0.0027625" pos="0.63 0 1.207" material="panel_color" euler="90 90 0" />
	</body>

	<body name="panel_9_oc">
		<geom type="box" size="0.200025 0.200025 0.0027625" pos=".42 0.13 1.207" material="panel_color" euler="90 0 0" />
		<joint name="panel_9_oc" type="hinge" pos=".42 0.13 .88" axis="90 0 0" limited="true" range="-15 15"/>
	</body>

	<body name="panel_3_oc">
		<geom type="box" size="0.200025 0.200025 0.0027625" pos=".42 -0.13 1.207" material="panel_color" euler="90 0 90" />
		<joint name="panel_3_oc" type="hinge" pos=".42 -0.13 .88" axis="90 0 0" limited="true" range="-15 15"/>
	</body>

</worldbody>

	<actuator>
      <motor name='left_head'	 		joint='left_head'   gear='200'      ctrlrange="-100.0 100.0"/>
      <motor name='right_head'	 	joint='right_head'  gear='200'      ctrlrange="-100.0 100.0"/>
      <motor name='left_neck'	 		joint='left_neck'   gear='200'      ctrlrange="-100.0 100.0"/>
      <motor name='right_neck'	 	joint='right_neck'  gear='200'      ctrlrange="-100.0 100.0" />
      <motor name='head_ball'	 		joint='head_ball'   gear='200'      ctrlrange="-100.0 100.0" />
      <motor name='panel_9_oc'	 	joint='panel_9_oc'  gear='200'      ctrlrange="-100.0 100.0" />
      <motor name='panel_3_oc'	 	joint='panel_3_oc'  gear='200'      ctrlrange="-100.0 100.0" />
   </actuator>
</mujoco>
